Workbook
Name Slicer_Package_Size: #N/A
Name Slicer_Package_Type: #N/A
Name Slicer_Protection: #N/A

Sheet Working Sheet
F1: Value (in 1000 $) | I1: Volume (in 1000)
F2: 2022 | G2: 2023 | H2: YTD 24 | I2: 2022 | J2: 2023 | K2: YTD 24
A3: FreshClean | B3: BRAND | C3: PACKAGE TYPE | D3: PROTECTION / CARE | E3: PACKAGE SIZE | F3: 31416.343 | G3: 32432.398 | H3: 17382.01 | I3: 1194607.9 | J3: 1188013.2 | K3: 600950.98
A4: Nova Garbagnate | B4: MANUFACTURER | F4: 1.935 | G4: 0.624 | I4: 24.8229 | J4: 9.4086 | M4: =IF(B3="ITEM",A3,"")
A5: BABY 2000 (Nova Garbagnate) | B5: BRAND | F5: 1.935 | G5: 0.624 | I5: 24.8229 | J5: 9.4086 | M5: =IF(B4="ITEM",A4,"")
A6: BABY2000 CAMOMILLA W 20 BAG ABA SRL | B6: ITEM | C6: BAGS | D6: WITHOUT EXTRA PROTECTCARE INDICATION | E6: 20 | F6: 1.935 | G6: 0.624 | I6: 24.8229 | J6: 9.4086 | M6: =IF(B5="ITEM",A5,"")
A7: BeneCare | B7: MANUFACTURER | F7: 0.0109 | I7: 0.16 | M7: =IF(B6="ITEM",A6,"") -> BABY2000 CAMOMILLA W 20 BAG ABA SRL | N7: =IF(B4="MANUFACTURER",A4,N6) -> Nova Garbagnate | O7: =IF(B5="BRAND",A5,O6) -> BABY 2000 (Nova Garbagnate) | P7: =IF(B6="ITEM",N7,"") -> Nova Garbagnate | R7: =IF(B6="ITEM",O7,"") -> BABY 2000 (Nova Garbagnate) | T7: BABY2000 CAMOMILLA W 20 BAG ABA SRL | U7: =IF(B6="ITEM",C6,"") -> BAGS | V7: =IF(B6="ITEM",D6,"") -> WITHOUT EXTRA PROTECTCARE INDICATION | W7: =IF(B6="ITEM",E6,"") -> 20 | X7: =IF(B6 = "ITEM",F6,"") -> 1.935 | Y7: =IF(B6="ITEM",G6,"") -> 0.624 | Z7: =IF(B6="ITEM",H6,"") -> 0 | AA7: =IF(B6="ITEM",I6,"") -> 24.8229 | AB7: =IF(B6="ITEM",J6,"") -> 9.4086 | AC7: =IF(B6="ITEM",K6,"") -> 0
A8: BAMBO (BeneCare) | B8: BRAND | F8: 0.0109 | I8: 0.16 | M8: =IF(B7="ITEM",A7,"") | N8: =IF(B5="MANUFACTURER",A5,N7) -> Nova Garbagnate | O8: =IF(B6="BRAND",A6,O7) -> BABY 2000 (Nova Garbagnate) | P8: =IF(B7="ITEM",N8,"") | R8: =IF(B7="ITEM",O8,"") | U8: =IF(B7="ITEM",C7,"") | V8: =IF(B7="ITEM",D7,"") | W8: =IF(B7="ITEM",E7,"") | X8: =IF(B7 = "ITEM",F7,"") | Y8: =IF(B7="ITEM",G7,"") | Z8: =IF(B7="ITEM",H7,"") | AA8: =IF(B7="ITEM",I7,"") | AB8: =IF(B7="ITEM",J7,"") | AC8: =IF(B7="ITEM",K7,"")
A9: BAMBO NATURE W 10 BAG | B9: ITEM | C9: BAGS | D9: WITHOUT EXTRA PROTECTCARE INDICATION | E9: 10 | M9: =IF(B8="ITEM",A8,"") | N9: =IF(B6="MANUFACTURER",A6,N8) -> Nova Garbagnate | O9: =IF(B7="BRAND",A7,O8) -> BABY 2000 (Nova Garbagnate) | P9: =IF(B8="ITEM",N9,"") | R9: =IF(B8="ITEM",O9,"") | U9: =IF(B8="ITEM",C8,"") | V9: =IF(B8="ITEM",D8,"") | W9: =IF(B8="ITEM",E8,"") | X9: =IF(B8 = "ITEM",F8,"") | Y9: =IF(B8="ITEM",G8,"") | Z9: =IF(B8="ITEM",H8,"") | AA9: =IF(B8="ITEM",I8,"") | AB9: =IF(B8="ITEM",J8,"") | AC9: =IF(B8="ITEM",K8,"")
A10: BAMBO NATURE W 50 BAG | B10: ITEM | C10: BAGS | D10: WITHOUT EXTRA PROTECTCARE INDICATION | E10: 50 | M10: =IF(B9="ITEM",A9,"") -> BAMBO NATURE W 10 BAG | N10: =IF(B7="MANUFACTURER",A7,N9) -> BeneCare | O10: =IF(B8="BRAND",A8,O9) -> BAMBO (BeneCare) | P10: =IF(B9="ITEM",N10,"") -> BeneCare | R10: =IF(B9="ITEM",O10,"") -> BAMBO (BeneCare) | T10: BAMBO NATURE W 10 BAG | U10: =IF(B9="ITEM",C9,"") -> BAGS | V10: =IF(B9="ITEM",D9,"") -> WITHOUT EXTRA PROTECTCARE INDICATION | W10: =IF(B9="ITEM",E9,"") -> 10 | X10: =IF(B9 = "ITEM",F9,"") -> 0 | Y10: =IF(B9="ITEM",G9,"") -> 0 | Z10: =IF(B9="ITEM",H9,"") -> 0 | AA10: =IF(B9="ITEM",I9,"") -> 0 | AB10: =IF(B9="ITEM",J9,"") -> 0 | AC10: =IF(B9="ITEM",K9,"") -> 0
A11: BAMBO NATURE 0%PERFUME W 80 BAG | B11: ITEM | C11: BAGS | D11: WITHOUT EXTRA PROTECTCARE INDICATION | E11: 80 | M11: =IF(B10="ITEM",A10,"") -> BAMBO NATURE W 50 BAG | N11: =IF(B8="MANUFACTURER",A8,N10) -> BeneCare | O11: =IF(B9="BRAND",A9,O10) -> BAMBO (BeneCare) | P11: =IF(B10="ITEM",N11,"") -> BeneCare | R11: =IF(B10="ITEM",O11,"") -> BAMBO (BeneCare) | T11: BAMBO NATURE W 50 BAG | U11: =IF(B10="ITEM",C10,"") -> BAGS | V11: =IF(B10="ITEM",D10,"") -> WITHOUT EXTRA PROTECTCARE INDICATION | W11: =IF(B10="ITEM",E10,"") -> 50 | X11: =IF(B10 = "ITEM",F10,"") -> 0 | Y11: =IF(B10="ITEM",G10,"") -> 0 | Z11: =IF(B10="ITEM",H10,"") -> 0 | AA11: =IF(B10="ITEM",I10,"") -> 0 | AB11: =IF(B10="ITEM",J10,"") -> 0 | AC11: =IF(B10="ITEM",K10,"") -> 0
A12: BAMBO NATURE W 80 BAG KAPAK | B12: ITEM | C12: BAGS | D12: WITHOUT EXTRA PROTECTCARE INDICATION | E12: 80 | F12: 0.0109 | I12: 0.16 | M12: =IF(B11="ITEM",A11,"") -> BAMBO NATURE 0%PERFUME W 80 BAG | N12: =IF(B9="MANUFACTURER",A9,N11) -> BeneCare | O12: =IF(B10="BRAND",A10,O11) -> BAMBO (BeneCare) | P12: =IF(B11="ITEM",N12,"") -> BeneCare | R12: =IF(B11="ITEM",O12,"") -> BAMBO (BeneCare) | T12: BAMBO NATURE 0%PERFUME W 80 BAG | U12: =IF(B11="ITEM",C11,"") -> BAGS | V12: =IF(B11="ITEM",D11,"") -> WITHOUT EXTRA PROTECTCARE INDICATION | W12: =IF(B11="ITEM",E11,"") -> 80 | X12: =IF(B11 = "ITEM",F11,"") -> 0 | Y12: =IF(B11="ITEM",G11,"") -> 0 | Z12: =IF(B11="ITEM",H11,"") -> 0 | AA12: =IF(B11="ITEM",I11,"") -> 0 | AB12: =IF(B11="ITEM",J11,"") -> 0 | AC12: =IF(B11="ITEM",K11,"") -> 0
A13: VigaLife | B13: MANUFACTURER | F13: 3341.5013 | G13: 3428.0437 | H13: 1852.1969 | I13: 125970.25 | J13: 127615.61 | K13: 64977.618 | M13: =IF(B12="ITEM",A12,"") -> BAMBO NATURE W 80 BAG KAPAK | N13: =IF(B10="MANUFACTURER",A10,N12) -> BeneCare | O13: =IF(B11="BRAND",A11,O12) -> BAMBO (BeneCare) | P13: =IF(B12="ITEM",N13,"") -> BeneCare | R13: =IF(B12="ITEM",O13,"") -> BAMBO (BeneCare) | T13: BAMBO NATURE W 80 BAG KAPAK | U13: =IF(B12="ITEM",C12,"") -> BAGS | V13: =IF(B12="ITEM",D12,"") -> WITHOUT EXTRA PROTECTCARE INDICATION | W13: =IF(B12="ITEM",E12,"") -> 80 | X13: =IF(B12 = "ITEM",F12,"") -> 0.0109 | Y13: =IF(B12="ITEM",G12,"") -> 0 | Z13: =IF(B12="ITEM",H12,"") -> 0 | AA13: =IF(B12="ITEM",I12,"") -> 0.16 | AB13: =IF(B12="ITEM",J12,"") -> 0 | AC13: =IF(B12="ITEM",K12,"") -> 0
A14: BABY CREMA (VigaLife) | B14: BRAND | F14: 3341.5013 | G14: 3428.0437 | H14: 1852.1969 | I14: 125970.25 | J14: 127615.61 | K14: 64977.618 | M14: =IF(B13="ITEM",A13,"") | N14: =IF(B11="MANUFACTURER",A11,N13) -> BeneCare | O14: =IF(B12="BRAND",A12,O13) -> BAMBO (BeneCare) | P14: =IF(B13="ITEM",N14,"") | R14: =IF(B13="ITEM",O14,"") | U14: =IF(B13="ITEM",C13,"") | V14: =IF(B13="ITEM",D13,"") | W14: =IF(B13="ITEM",E13,"") | X14: =IF(B13 = "ITEM",F13,"") | Y14: =IF(B13="ITEM",G13,"") | Z14: =IF(B13="ITEM",H13,"") | AA14: =IF(B13="ITEM",I13,"") | AB14: =IF(B13="ITEM",J13,"") | AC14: =IF(B13="ITEM",K13,"")
A15: BABY CREMA PLAY TIME CAMOMILE W 100 PINK | B15: ITEM | C15: BAGS | D15: PH BALANCED | E15: 100 | F15: 81.4674 | G15: 92.903 | H15: 52.5119 | I15: 2980.7043 | J15: 3415.3554 | K15: 1823.0734 | M15: =IF(B14="ITEM",A14,"") | N15: =IF(B12="MANUFACTURER",A12,N14) -> BeneCare | O15: =IF(B13="BRAND",A13,O14) -> BAMBO (BeneCare) | P15: =IF(B14="ITEM",N15,"") | R15: =IF(B14="ITEM",O15,"") | U15: =IF(B14="ITEM",C14,"") | V15: =IF(B14="ITEM",D14,"") | W15: =IF(B14="ITEM",E14,"") | X15: =IF(B14 = "ITEM",F14,"") | Y15: =IF(B14="ITEM",G14,"") | Z15: =IF(B14="ITEM",H14,"") | AA15: =IF(B14="ITEM",I14,"") | AB15: =IF(B14="ITEM",J14,"") | AC15: =IF(B14="ITEM",K14,"")
A16: BABYCREMA PLAYTIME CAMOMILE W 100 ORANGE | B16: ITEM | C16: BAGS | D16: PH BALANCED | E16: 100 | F16: 165.228 | G16: 172.6843 | H16: 91.1357 | I16: 5930.9056 | J16: 6183.6273 | K16: 3125.7987 | M16: =IF(B15="ITEM",A15,"") -> BABY CREMA PLAY TIME CAMOMILE W 100 PINK | N16: =IF(B13="MANUFACTURER",A13,N15) -> VigaLife | O16: =IF(B14="BRAND",A14,O15) -> BABY CREMA (VigaLife) | P16: =IF(B15="ITEM",N16,"") -> VigaLife | R16: =IF(B15="ITEM",O16,"") -> BABY CREMA (VigaLife) | T16: BABY CREMA PLAY TIME CAMOMILE W 100 PINK | U16: =IF(B15="ITEM",C15,"") -> BAGS | V16: =IF(B15="ITEM",D15,"") -> PH BALANCED | W16: =IF(B15="ITEM",E15,"") -> 100 | X16: =IF(B15 = "ITEM",F15,"") -> 81.4674 | Y16: =IF(B15="ITEM",G15,"") -> 92.903 | Z16: =IF(B15="ITEM",H15,"") -> 52.5119 | AA16: =IF(B15="ITEM",I15,"") -> 2980.7043 | AB16: =IF(B15="ITEM",J15,"") -> 3415.3554 | AC16: =IF(B15="ITEM",K15,"") -> 1823.0734
A17: BABY CREMA CAMOMIL W 120 BAG KAPAK | B17: ITEM | C17: BAGS | D17: PH BALANCED | E17: 120 | F17: 842.8724 | G17: 745.3358 | H17: 366.9589 | I17: 38888.54 | J17: 31985 | K17: 14135.173 | M17: =IF(B16="ITEM",A16,"") -> BABYCREMA PLAYTIME CAMOMILE W 100 ORANGE | N17: =IF(B14="MANUFACTURER",A14,N16) -> VigaLife | O17: =IF(B15="BRAND",A15,O16) -> BABY CREMA (VigaLife) | P17: =IF(B16="ITEM",N17,"") -> VigaLife | R17: =IF(B16="ITEM",O17,"") -> BABY CREMA (VigaLife) | T17: BABYCREMA PLAYTIME CAMOMILE W 100 ORANGE | U17: =IF(B16="ITEM",C16,"") -> BAGS | V17: =IF(B16="ITEM",D16,"") -> PH BALANCED | W17: =IF(B16="ITEM",E16,"") -> 100 | X17: =IF(B16 = "ITEM",F16,"") -> 165.228 | Y17: =IF(B16="ITEM",G16,"") -> 172.6843 | Z17: =IF(B16="ITEM",H16,"") -> 91.1357 | AA17: =IF(B16="ITEM",I16,"") -> 5930.9056 | AB17: =IF(B16="ITEM",J16,"") -> 6183.6273 | AC17: =IF(B16="ITEM",K16,"") -> 3125.7987
A18: BABY CREMA ALOE 15 BAG | B18: ITEM | C18: BAGS | D18: WITHOUT EXTRA PROTECTCARE INDICATION | E18: 15 | F18: 12.7748 | G18: 10.866 | H18: 6.7743 | I18: 151.2668 | J18: 127.1868 | K18: 77.4594 | M18: =IF(B17="ITEM",A17,"") -> BABY CREMA CAMOMIL W 120 BAG KAPAK | N18: =IF(B15="MANUFACTURER",A15,N17) -> VigaLife | O18: =IF(B16="BRAND",A16,O17) -> BABY CREMA (VigaLife) | P18: =IF(B17="ITEM",N18,"") -> VigaLife | R18: =IF(B17="ITEM",O18,"") -> BABY CREMA (VigaLife) | T18: BABY CREMA CAMOMIL W 120 BAG KAPAK | U18: =IF(B17="ITEM",C17,"") -> BAGS | V18: =IF(B17="ITEM",D17,"") -> PH BALANCED | W18: =IF(B17="ITEM",E17,"") -> 120 | X18: =IF(B17 = "ITEM",F17,"") -> 842.8724 | Y18: =IF(B17="ITEM",G17,"") -> 745.3358 | Z18: =IF(B17="ITEM",H17,"") -> 366.9589 | AA18: =IF(B17="ITEM",I17,"") -> 38888.54 | AB18: =IF(B17="ITEM",J17,"") -> 31985 | AC18: =IF(B17="ITEM",K17,"") -> 14135.173
A19: BABY CREMA CAMOMIL W 15 BAG | B19: ITEM | C19: BAGS | D19: WITHOUT EXTRA PROTECTCARE INDICATION | E19: 15 | F19: 20.0553 | G19: 17.8361 | H19: 11.1871 | I19: 231.0878 | J19: 217.7118 | K19: 141.008 | M19: =IF(B18="ITEM",A18,"") -> BABY CREMA ALOE 15 BAG | N19: =IF(B16="MANUFACTURER",A16,N18) -> VigaLife | O19: =IF(B17="BRAND",A17,O18) -> BABY CREMA (VigaLife) | P19: =IF(B18="ITEM",N19,"") -> VigaLife | R19: =IF(B18="ITEM",O19,"") -> BABY CREMA (VigaLife) | T19: BABY CREMA ALOE 15 BAG | U19: =IF(B18="ITEM",C18,"") -> BAGS | V19: =IF(B18="ITEM",D18,"") -> WITHOUT EXTRA PROTECTCARE INDICATION | W19: =IF(B18="ITEM",E18,"") -> 15 | X19: =IF(B18 = "ITEM",F18,"") -> 12.7748 | Y19: =IF(B18="ITEM",G18,"") -> 10.866 | Z19: =IF(B18="ITEM",H18,"") -> 6.7743 | AA19: =IF(B18="ITEM",I18,"") -> 151.2668 | AB19: =IF(B18="ITEM",J18,"") -> 127.1868 | AC19: =IF(B18="ITEM",K18,"") -> 77.4594
A20: BABY CREMA PH5.5 W 3X15/1FR BAG &&& | B20: ITEM | C20: BAGS | D20: PH BALANCED | E20: 15 | F20: 1.2461 | G20: 7.7651 | H20: 2.2378 | I20: 20.9609 | J20: 127.6666 | K20: 33.571 | M20: =IF(B19="ITEM",A19,"") -> BABY CREMA CAMOMIL W 15 BAG | N20: =IF(B17="MANUFACTURER",A17,N19) -> VigaLife | O20: =IF(B18="BRAND",A18,O19) -> BABY CREMA (VigaLife) | P20: =IF(B19="ITEM",N20,"") -> VigaLife | R20: =IF(B19="ITEM",O20,"") -> BABY CREMA (VigaLife) | T20: BABY CREMA CAMOMIL W 15 BAG | U20: =IF(B19="ITEM",C19,"") -> BAGS | V20: =IF(B19="ITEM",D19,"") -> WITHOUT EXTRA PROTECTCARE INDICATION | W20: =IF(B19="ITEM",E19,"") -> 15 | X20: =IF(B19 = "ITEM",F19,"") -> 20.0553 | Y20: =IF(B19="ITEM",G19,"") -> 17.8361 | Z20: =IF(B19="ITEM",H19,"") -> 11.1871 | AA20: =IF(B19="ITEM",I19,"") -> 231.0878 | AB20: =IF(B19="ITEM",J19,"") -> 217.7118 | AC20: =IF(B19="ITEM",K19,"") -> 141.008
A21: BABY CREMA WATER 99% W 15 BAG | B21: ITEM | C21: BAGS | D21: ALCOHOL FREE | E21: 15 | F21: 9.6472 | G21: 10.7577 | H21: 7.0723 | I21: 112.2061 | J21: 131.0528 | K21: 85.7198 | M21: =IF(B20="ITEM",A20,"") -> BABY CREMA PH5.5 W 3X15/1FR BAG &&& | N21: =IF(B18="MANUFACTURER",A18,N20) -> VigaLife | O21: =IF(B19="BRAND",A19,O20) -> BABY CREMA (VigaLife) | P21: =IF(B20="ITEM",N21,"") -> VigaLife | R21: =IF(B20="ITEM",O21,"") -> BABY CREMA (VigaLife) | T21: BABY CREMA PH5.5 W 3X15/1FR BAG &&& | U21: =IF(B20="ITEM",C20,"") -> BAGS | V21: =IF(B20="ITEM",D20,"") -> PH BALANCED | W21: =IF(B20="ITEM",E20,"") -> 15 | X21: =IF(B20 = "ITEM",F20,"") -> 1.2461 | Y21: =IF(B20="ITEM",G20,"") -> 7.7651 | Z21: =IF(B20="ITEM",H20,"") -> 2.2378 | AA21: =IF(B20="ITEM",I20,"") -> 20.9609 | AB21: =IF(B20="ITEM",J20,"") -> 127.6666 | AC21: =IF(B20="ITEM",K20,"") -> 33.571
A22: BABY CREMA CAMOMIL W 40 BAG | B22: ITEM | C22: BAGS | D22: WITHOUT EXTRA PROTECTCARE INDICATION | E22: 40 | F22: 0.1235 | I22: 2.28 | M22: =IF(B21="ITEM",A21,"") -> BABY CREMA WATER 99% W 15 BAG | N22: =IF(B19="MANUFACTURER",A19,N21) -> VigaLife | O22: =IF(B20="BRAND",A20,O21) -> BABY CREMA (VigaLife) | P22: =IF(B21="ITEM",N22,"") -> VigaLife | R22: =IF(B21="ITEM",O22,"") -> BABY CREMA (VigaLife) | T22: BABY CREMA WATER 99% W 15 BAG | U22: =IF(B21="ITEM",C21,"") -> BAGS | V22: =IF(B21="ITEM",D21,"") -> ALCOHOL FREE | W22: =IF(B21="ITEM",E21,"") -> 15 | X22: =IF(B21 = "ITEM",F21,"") -> 9.6472 | Y22: =IF(B21="ITEM",G21,"") -> 10.7577 | Z22: =IF(B21="ITEM",H21,"") -> 7.0723 | AA22: =IF(B21="ITEM",I21,"") -> 112.2061 | AB22: =IF(B21="ITEM",J21,"") -> 131.0528 | AC22: =IF(B21="ITEM",K21,"") -> 85.7198
A23: BABY CREMA COTTON&PANTENOL W 4X56 BAG | B23: ITEM | C23: BAGS | D23: PH BALANCED | E23: 56 | H23: 7.1128 | K23: 247.099 | M23: =IF(B22="ITEM",A22,"") -> BABY CREMA CAMOMIL W 40 BAG | N23: =IF(B20="MANUFACTURER",A20,N22) -> VigaLife | O23: =IF(B21="BRAND",A21,O22) -> BABY CREMA (VigaLife) | P23: =IF(B22="ITEM",N23,"") -> VigaLife | R23: =IF(B22="ITEM",O23,"") -> BABY CREMA (VigaLife) | T23: BABY CREMA CAMOMIL W 40 BAG | U23: =IF(B22="ITEM",C22,"") -> BAGS | V23: =IF(B22="ITEM",D22,"") -> WITHOUT EXTRA PROTECTCARE INDICATION | W23: =IF(B22="ITEM",E22,"") -> 40 | X23: =IF(B22 = "ITEM",F22,"") -> 0.1235 | Y23: =IF(B22="ITEM",G22,"") -> 0 | Z23: =IF(B22="ITEM",H22,"") -> 0 | AA23: =IF(B22="ITEM",I22,"") -> 2.28 | AB23: =IF(B22="ITEM",J22,"") -> 0 | AC23: =IF(B22="ITEM",K22,"") -> 0
A24: BABY CREMA COTTON&PANTENOL W 56 BAG | B24: ITEM | C24: BAGS | D24: PH BALANCED | E24: 56 | F24: 0.1831 | G24: 0.1116 | H24: 0.387 | I24: 5.8885 | J24: 3.791 | K24: 14.3827 | M24: =IF(B23="ITEM",A23,"") -> BABY CREMA COTTON&PANTENOL W 4X56 BAG | N24: =IF(B21="MANUFACTURER",A21,N23) -> VigaLife | O24: =IF(B22="BRAND",A22,O23) -> BABY CREMA (VigaLife) | P24: =IF(B23="ITEM",N24,"") -> VigaLife | R24: =IF(B23="ITEM",O24,"") -> BABY CREMA (VigaLife) | T24: BABY CREMA COTTON&PANTENOL W 4X56 BAG | U24: =IF(B23="ITEM",C23,"") -> BAGS | V24: =IF(B23="ITEM",D23,"") -> PH BALANCED | W24: =IF(B23="ITEM",E23,"") -> 56 | X24: =IF(B23 = "ITEM",F23,"") -> 0 | Y24: =IF(B23="ITEM",G23,"") -> 0 | Z24: =IF(B23="ITEM",H23,"") -> 7.1128 | AA24: =IF(B23="ITEM",I23,"") -> 0 | AB24: =IF(B23="ITEM",J23,"") -> 0 | AC24: =IF(B23="ITEM",K23,"") -> 247.099
A25: BABY CREMA ALOE 64 BAG | B25: ITEM | C25: BAGS | D25: WITHOUT EXTRA PROTECTCARE INDICATION | E25: 64 | F25: 1.8939 | H25: 0.2252 | I25: 49.9726 | K25: 6.9501 | M25: =IF(B24="ITEM",A24,"") -> BABY CREMA COTTON&PANTENOL W 56 BAG | N25: =IF(B22="MANUFACTURER",A22,N24) -> VigaLife | O25: =IF(B23="BRAND",A23,O24) -> BABY CREMA (VigaLife) | P25: =IF(B24="ITEM",N25,"") -> VigaLife | R25: =IF(B24="ITEM",O25,"") -> BABY CREMA (VigaLife) | T25: BABY CREMA COTTON&PANTENOL W 56 BAG | U25: =IF(B24="ITEM",C24,"") -> BAGS | V25: =IF(B24="ITEM",D24,"") -> PH BALANCED | W25: =IF(B24="ITEM",E24,"") -> 56 | X25: =IF(B24 = "ITEM",F24,"") -> 0.1831 | Y25: =IF(B24="ITEM",G24,"") -> 0.1116 | Z25: =IF(B24="ITEM",H24,"") -> 0.387 | AA25: =IF(B24="ITEM",I24,"") -> 5.8885 | AB25: =IF(B24="ITEM",J24,"") -> 3.791 | AC25: =IF(B24="ITEM",K24,"") -> 14.3827
A26: BABY CREMA CAMOMIL W 64 BAG | B26: ITEM | C26: BAGS | D26: WITHOUT EXTRA PROTECTCARE INDICATION | E26: 64 | F26: 1.3515 | G26: 0.0017 | I26: 37.3226 | J26: 0.064 | M26: =IF(B25="ITEM",A25,"") -> BABY CREMA ALOE 64 BAG | N26: =IF(B23="MANUFACTURER",A23,N25) -> VigaLife | O26: =IF(B24="BRAND",A24,O25) -> BABY CREMA (VigaLife) | P26: =IF(B25="ITEM",N26,"") -> VigaLife | R26: =IF(B25="ITEM",O26,"") -> BABY CREMA (VigaLife) | T26: BABY CREMA ALOE 64 BAG | U26: =IF(B25="ITEM",C25,"") -> BAGS | V26: =IF(B25="ITEM",D25,"") -> WITHOUT EXTRA PROTECTCARE INDICATION | W26: =IF(B25="ITEM",E25,"") -> 64 | X26: =IF(B25 = "ITEM",F25,"") -> 1.8939 | Y26: =IF(B25="ITEM",G25,"") -> 0 | Z26: =IF(B25="ITEM",H25,"") -> 0.2252 | AA26: =IF(B25="ITEM",I25,"") -> 49.9726 | AB26: =IF(B25="ITEM",J25,"") -> 0 | AC26: =IF(B25="ITEM",K25,"") -> 6.9501
A27: BABY CREMA PLAY TIME CAMOMIL W 64 BAG | B27: ITEM | C27: BAGS | D27: PH BALANCED | E27: 64 | F27: 5.8978 | G27: 0.1087 | I27: 169.5808 | J27: 3.3823 | M27: =IF(B26="ITEM",A26,"") -> BABY CREMA CAMOMIL W 64 BAG | N27: =IF(B24="MANUFACTURER",A24,N26) -> VigaLife | O27: =IF(B25="BRAND",A25,O26) -> BABY CREMA (VigaLife) | P27: =IF(B26="ITEM",N27,"") -> VigaLife | R27: =IF(B26="ITEM",O27,"") -> BABY CREMA (VigaLife) | T27: BABY CREMA CAMOMIL W 64 BAG | U27: =IF(B26="ITEM",C26,"") -> BAGS | V27: =IF(B26="ITEM",D26,"") -> WITHOUT EXTRA PROTECTCARE INDICATION | W27: =IF(B26="ITEM",E26,"") -> 64 | X27: =IF(B26 = "ITEM",F26,"") -> 1.3515 | Y27: =IF(B26="ITEM",G26,"") -> 0.0017 | Z27: =IF(B26="ITEM",H26,"") -> 0 | AA27: =IF(B26="ITEM",I26,"") -> 37.3226 | AB27: =IF(B26="ITEM",J26,"") -> 0.064 | AC27: =IF(B26="ITEM",K26,"") -> 0
A28: BABYCREMA CAMOMIL W 4X64 BAG SUPERTSENA | B28: ITEM | C28: BAGS | D28: ALCOHOL FREE | E28: 64 | F28: 0.6967 | G28: 28.3929 | H28: 2.1978 | I28: 25.6063 | J28: 1226.3662 | K28: 96.4388 | M28: =IF(B27="ITEM",A27,"") -> BABY CREMA PLAY TIME CAMOMIL W 64 BAG | N28: =IF(B25="MANUFACTURER",A25,N27) -> VigaLife | O28: =IF(B26="BRAND",A26,O27) -> BABY CREMA (VigaLife) | P28: =IF(B27="ITEM",N28,"") -> VigaLife | R28: =IF(B27="ITEM",O28,"") -> BABY CREMA (VigaLife) | T28: BABY CREMA PLAY TIME CAMOMIL W 64 BAG | U28: =IF(B27="ITEM",C27,"") -> BAGS | V28: =IF(B27="ITEM",D27,"") -> PH BALANCED | W28: =IF(B27="ITEM",E27,"") -> 64 | X28: =IF(B27 = "ITEM",F27,"") -> 5.8978 | Y28: =IF(B27="ITEM",G27,"") -> 0.1087 | Z28: =IF(B27="ITEM",H27,"") -> 0 | AA28: =IF(B27="ITEM",I27,"") -> 169.5808 | AB28: =IF(B27="ITEM",J27,"") -> 3.3823 | AC28: =IF(B27="ITEM",K27,"") -> 0
A29: BABY CREMA ALOE&ALMOND OIL W 72 BAG | B29: ITEM | C29: BAGS | D29: WITHOUT EXTRA PROTECTCARE INDICATION | E29: 72 | F29: 117.6534 | G29: 68.1177 | H29: 28.3499 | I29: 3055.9406 | J29: 1781.8513 | K29: 711.0772 | M29: =IF(B28="ITEM",A28,"") -> BABYCREMA CAMOMIL W 4X64 BAG SUPERTSENA | N29: =IF(B26="MANUFACTURER",A26,N28) -> VigaLife | O29: =IF(B27="BRAND",A27,O28) -> BABY CREMA (VigaLife) | P29: =IF(B28="ITEM",N29,"") -> VigaLife | R29: =IF(B28="ITEM",O29,"") -> BABY CREMA (VigaLife) | T29: BABYCREMA CAMOMIL W 4X64 BAG SUPERTSENA | U29: =IF(B28="ITEM",C28,"") -> BAGS | V29: =IF(B28="ITEM",D28,"") -> ALCOHOL FREE | W29: =IF(B28="ITEM",E28,"") -> 64 | X29: =IF(B28 = "ITEM",F28,"") -> 0.6967 | Y29: =IF(B28="ITEM",G28,"") -> 28.3929 | Z29: =IF(B28="ITEM",H28,"") -> 2.1978 | AA29: =IF(B28="ITEM",I28,"") -> 25.6063 | AB29: =IF(B28="ITEM",J28,"") -> 1226.3662 | AC29: =IF(B28="ITEM",K28,"") -> 96.4388
A30: BABY CREMA CAMOMIL&ALMOND W 72 BAG | B30: ITEM | C30: BAGS | D30: WITHOUT EXTRA PROTECTCARE INDICATION | E30: 72 | F30: 38.6778 | G30: 31.4983 | H30: 9.7551 | I30: 954.1122 | J30: 803.2852 | K30: 236.1983 | M30: =IF(B29="ITEM",A29,"") -> BABY CREMA ALOE&ALMOND OIL W 72 BAG | N30: =IF(B27="MANUFACTURER",A27,N29) -> VigaLife | O30: =IF(B28="BRAND",A28,O29) -> BABY CREMA (VigaLife) | P30: =IF(B29="ITEM",N30,"") -> VigaLife | R30: =IF(B29="ITEM",O30,"") -> BABY CREMA (VigaLife) | T30: BABY CREMA ALOE&ALMOND OIL W 72 BAG | U30: =IF(B29="ITEM",C29,"") -> BAGS | V30: =IF(B29="ITEM",D29,"") -> WITHOUT EXTRA PROTECTCARE INDICATION | W30: =IF(B29="ITEM",E29,"") -> 72 | X30: =IF(B29 = "ITEM",F29,"") -> 117.6534 | Y30: =IF(B29="ITEM",G29,"") -> 68.1177 | Z30: =IF(B29="ITEM",H29,"") -> 28.3499 | AA30: =IF(B29="ITEM",I29,"") -> 3055.9406 | AB30: =IF(B29="ITEM",J29,"") -> 1781.8513 | AC30: =IF(B29="ITEM",K29,"") -> 711.0772
A31: BABY CREMA COTTON W 2X72BAG50%OT TS.VTOR | B31: ITEM | C31: BAGS | D31: PH BALANCED | E31: 72 | F31: 0.0612 | I31: 1.6046 | M31: =IF(B30="ITEM",A30,"") -> BABY CREMA CAMOMIL&ALMOND W 72 BAG | N31: =IF(B28="MANUFACTURER",A28,N30) -> VigaLife | O31: =IF(B29="BRAND",A29,O30) -> BABY CREMA (VigaLife) | P31: =IF(B30="ITEM",N31,"") -> VigaLife | R31: =IF(B30="ITEM",O31,"") -> BABY CREMA (VigaLife) | T31: BABY CREMA CAMOMIL&ALMOND W 72 BAG | U31: =IF(B30="ITEM",C30,"") -> BAGS | V31: =IF(B30="ITEM",D30,"") -> WITHOUT EXTRA PROTECTCARE INDICATION | W31: =IF(B30="ITEM",E30,"") -> 72 | X31: =IF(B30 = "ITEM",F30,"") -> 38.6778 | Y31: =IF(B30="ITEM",G30,"") -> 31.4983 | Z31: =IF(B30="ITEM",H30,"") -> 9.7551 | AA31: =IF(B30="ITEM",I30,"") -> 954.1122 | AB31: =IF(B30="ITEM",J30,"") -> 803.2852 | AC31: =IF(B30="ITEM",K30,"") -> 236.1983
A32: BABY CREMA COTTON&PANTENOL W 72 BAG | B32: ITEM | C32: BAGS | D32: PH BALANCED | E32: 72 | F32: 36.5218 | G32: 5.1192 | H32: 1.1213 | I32: 1199.5277 | J32: 135.3687 | K32: 30.5544 | M32: =IF(B31="ITEM",A31,"") -> BABY CREMA COTTON W 2X72BAG50%OT TS.VTOR | N32: =IF(B29="MANUFACTURER",A29,N31) -> VigaLife | O32: =IF(B30="BRAND",A30,O31) -> BABY CREMA (VigaLife) | P32: =IF(B31="ITEM",N32,"") -> VigaLife | R32: =IF(B31="ITEM",O32,"") -> BABY CREMA (VigaLife) | T32: BABY CREMA COTTON W 2X72BAG50%OT TS.VTOR | U32: =IF(B31="ITEM",C31,"") -> BAGS | V32: =IF(B31="ITEM",D31,"") -> PH BALANCED | W32: =IF(B31="ITEM",E31,"") -> 72 | X32: =IF(B31 = "ITEM",F31,"") -> 0.0612 | Y32: =IF(B31="ITEM",G31,"") -> 0 | Z32: =IF(B31="ITEM",H31,"") -> 0 | AA32: =IF(B31="ITEM",I31,"") -> 1.6046 | AB32: =IF(B31="ITEM",J31,"") -> 0 | AC32: =IF(B31="ITEM",K31,"") -> 0
A33: BABY CREMA NEVEN PH5.5 W 72 BAG | B33: ITEM | C33: BAGS | D33: PH BALANCED | E33: 72 | F33: 21.9583 | G33: 39.4671 | H33: 10.7844 | I33: 726.314 | J33: 1508.4714 | K33: 314.5264 | M33: =IF(B32="ITEM",A32,"") -> BABY CREMA COTTON&PANTENOL W 72 BAG | N33: =IF(B30="MANUFACTURER",A30,N32) -> VigaLife | O33: =IF(B31="BRAND",A31,O32) -> BABY CREMA (VigaLife) | P33: =IF(B32="ITEM",N33,"") -> VigaLife | R33: =IF(B32="ITEM",O33,"") -> BABY CREMA (VigaLife) | T33: BABY CREMA COTTON&PANTENOL W 72 BAG | U33: =IF(B32="ITEM",C32,"") -> BAGS | V33: =IF(B32="ITEM",D32,"") -> PH BALANCED | W33: =IF(B32="ITEM",E32,"") -> 72 | X33: =IF(B32 = "ITEM",F32,"") -> 36.5218 | Y33: =IF(B32="ITEM",G32,"") -> 5.1192 | Z33: =IF(B32="ITEM",H32,"") -> 1.1213 | AA33: =IF(B32="ITEM",I32,"") -> 1199.5277 | AB33: =IF(B32="ITEM",J32,"") -> 135.3687 | AC33: =IF(B32="ITEM",K32,"") -> 30.5544
A34: BABY CREMA SMRADLIKA PH5.5 W 72 BAG | B34: ITEM | C34: BAGS | D34: PH BALANCED | E34: 72 | F34: 27.9836 | G34: 162.4105 | H34: 103.168 | I34: 928.8153 | J34: 5484.9445 | K34: 3446.0195 | M34: =IF(B33="ITEM",A33,"") -> BABY CREMA NEVEN PH5.5 W 72 BAG | N34: =IF(B31="MANUFACTURER",A31,N33) -> VigaLife | O34: =IF(B32="BRAND",A32,O33) -> BABY CREMA (VigaLife) | P34: =IF(B33="ITEM",N34,"") -> VigaLife | R34: =IF(B33="ITEM",O34,"") -> BABY CREMA (VigaLife) | T34: BABY CREMA NEVEN PH5.5 W 72 BAG | U34: =IF(B33="ITEM",C33,"") -> BAGS | V34: =IF(B33="ITEM",D33,"") -> PH BALANCED | W34: =IF(B33="ITEM",E33,"") -> 72 | X34: =IF(B33 = "ITEM",F33,"") -> 21.9583 | Y34: =IF(B33="ITEM",G33,"") -> 39.4671 | Z34: =IF(B33="ITEM",H33,"") -> 10.7844 | AA34: =IF(B33="ITEM",I33,"") -> 726.314 | AB34: =IF(B33="ITEM",J33,"") -> 1508.4714 | AC34: =IF(B33="ITEM",K33,"") -> 314.5264
A35: BABY CREMA WATER 99% W 72 BAG | B35: ITEM | C35: BAGS | D35: WITHOUT EXTRA PROTECTCARE INDICATION | E35: 72 | F35: 221.1702 | G35: 159.9896 | H35: 77.8656 | I35: 6715.8593 | J35: 4333.2688 | K35: 2035.5381 | M35: =IF(B34="ITEM",A34,"") -> BABY CREMA SMRADLIKA PH5.5 W 72 BAG | N35: =IF(B32="MANUFACTURER",A32,N34) -> VigaLife | O35: =IF(B33="BRAND",A33,O34) -> BABY CREMA (VigaLife) | P35: =IF(B34="ITEM",N35,"") -> VigaLife | R35: =IF(B34="ITEM",O35,"") -> BABY CREMA (VigaLife) | T35: BABY CREMA SMRADLIKA PH5.5 W 72 BAG | U35: =IF(B34="ITEM",C34,"") -> BAGS | V35: =IF(B34="ITEM",D34,"") -> PH BALANCED | W35: =IF(B34="ITEM",E34,"") -> 72 | X35: =IF(B34 = "ITEM",F34,"") -> 27.9836 | Y35: =IF(B34="ITEM",G34,"") -> 162.4105 | Z35: =IF(B34="ITEM",H34,"") -> 103.168 | AA35: =IF(B34="ITEM",I34,"") -> 928.8153 | AB35: =IF(B34="ITEM",J34,"") -> 5484.9445 | AC35: =IF(B34="ITEM",K34,"") -> 3446.0195
A36: BABYCREMA CAMOMILE W 2X72BAG50%OTTS.VTOR | B36: ITEM | C36: BAGS | D36: PH BALANCED | E36: 72 | F36: 6.4487 | G36: 1.6864 | I36: 194.6519 | J36: 50.7003 | M36: =IF(B35="ITEM",A35,"") -> BABY CREMA WATER 99% W 72 BAG | N36: =IF(B33="MANUFACTURER",A33,N35) -> VigaLife | O36: =IF(B34="BRAND",A34,O35) -> BABY CREMA (VigaLife) | P36: =IF(B35="ITEM",N36,"") -> VigaLife | R36: =IF(B35="ITEM",O36,"") -> BABY CREMA (VigaLife) | T36: BABY CREMA WATER 99% W 72 BAG | U36: =IF(B35="ITEM",C35,"") -> BAGS | V36: =IF(B35="ITEM",D35,"") -> WITHOUT EXTRA PROTECTCARE INDICATION | W36: =IF(B35="ITEM",E35,"") -> 72 | X36: =IF(B35 = "ITEM",F35,"") -> 221.1702 | Y36: =IF(B35="ITEM",G35,"") -> 159.9896 | Z36: =IF(B35="ITEM",H35,"") -> 77.8656 | AA36: =IF(B35="ITEM",I35,"") -> 6715.8593 | AB36: =IF(B35="ITEM",J35,"") -> 4333.2688 | AC36: =IF(B35="ITEM",K35,"") -> 2035.5381
A37: BABYCREMA COTTON&PANTENOL W 3X72/1FR BAG | B37: ITEM | C37: BAGS | D37: PH BALANCED | E37: 72 | M37: =IF(B36="ITEM",A36,"") -> BABYCREMA CAMOMILE W 2X72BAG50%OTTS.VTOR | N37: =IF(B34="MANUFACTURER",A34,N36) -> VigaLife | O37: =IF(B35="BRAND",A35,O36) -> BABY CREMA (VigaLife) | P37: =IF(B36="ITEM",N37,"") -> VigaLife | R37: =IF(B36="ITEM",O37,"") -> BABY CREMA (VigaLife) | T37: BABYCREMA CAMOMILE W 2X72BAG50%OTTS.VTOR | U37: =IF(B36="ITEM",C36,"") -> BAGS | V37: =IF(B36="ITEM",D36,"") -> PH BALANCED | W37: =IF(B36="ITEM",E36,"") -> 72 | X37: =IF(B36 = "ITEM",F36,"") -> 6.4487 | Y37: =IF(B36="ITEM",G36,"") -> 1.6864 | Z37: =IF(B36="ITEM",H36,"") -> 0 | AA37: =IF(B36="ITEM",I36,"") -> 194.6519 | AB37: =IF(B36="ITEM",J36,"") -> 50.7003 | AC37: =IF(B36="ITEM",K36,"") -> 0
A38: BABYCREMA PLAYTIME CAMOMIL W 72 BAG KAPA | B38: ITEM | C38: BAGS | D38: PH BALANCED | E38: 72 | F38: 1663.8369 | G38: 1815.6597 | H38: 1049.2486 | I38: 62012.673 | J38: 68679.966 | K38: 37856.882 | M38: =IF(B37="ITEM",A37,"") -> BABYCREMA COTTON&PANTENOL W 3X72/1FR BAG | N38: =IF(B35="MANUFACTURER",A35,N37) -> VigaLife | O38: =IF(B36="BRAND",A36,O37) -> BABY CREMA (VigaLife) | P38: =IF(B37="ITEM",N38,"") -> VigaLife | R38: =IF(B37="ITEM",O38,"") -> BABY CREMA (VigaLife) | T38: BABYCREMA COTTON&PANTENOL W 3X72/1FR BAG | U38: =IF(B37="ITEM",C37,"") -> BAGS | V38: =IF(B37="ITEM",D37,"") -> PH BALANCED | W38: =IF(B37="ITEM",E37,"") -> 72 | X38: =IF(B37 = "ITEM",F37,"") -> 0 | Y38: =IF(B37="ITEM",G37,"") -> 0 | Z38: =IF(B37="ITEM",H37,"") -> 0 | AA38: =IF(B37="ITEM",I37,"") -> 0 | AB38: =IF(B37="ITEM",J37,"") -> 0 | AC38: =IF(B37="ITEM",K37,"") -> 0
A39: BABY CREMA ALOE W 80 BAG | B39: ITEM | C39: BAGS | D39: WITHOUT EXTRA PROTECTCARE INDICATION | E39: 80 | F39: 1.7698 | G39: 0.3617 | H39: 0.2081 | I39: 50.2205 | J39: 12.0681 | K39: 5.4643 | M39: =IF(B38="ITEM",A38,"") -> BABYCREMA PLAYTIME CAMOMIL W 72 BAG KAPA | N39: =IF(B36="MANUFACTURER",A36,N38) -> VigaLife | O39: =IF(B37="BRAND",A37,O38) -> BABY CREMA (VigaLife) | P39: =IF(B38="ITEM",N39,"") -> VigaLife | R39: =IF(B38="ITEM",O39,"") -> BABY CREMA (VigaLife) | T39: BABYCREMA PLAYTIME CAMOMIL W 72 BAG KAPA | U39: =IF(B38="ITEM",C38,"") -> BAGS | V39: =IF(B38="ITEM",D38,"") -> PH BALANCED | W39: =IF(B38="ITEM",E38,"") -> 72 | X39: =IF(B38 = "ITEM",F38,"") -> 1663.8369 | Y39: =IF(B38="ITEM",G38,"") -> 1815.6597 | Z39: =IF(B38="ITEM",H38,"") -> 1049.2486 | AA39: =IF(B38="ITEM",I38,"") -> 62012.673 | AB39: =IF(B38="ITEM",J38,"") -> 68679.966 | AC39: =IF(B38="ITEM",K38,"") -> 37856.882
A40: BABY CREMA CAMOMIL W 80 BAG | B40: ITEM | C40: BAGS | D40: WITHOUT EXTRA PROTECTCARE INDICATION | E40: 80 | F40: 61.9819 | G40: 56.9702 | H40: 23.8948 | I40: 1524.2099 | J40: 1404.4859 | K40: 554.6842 | M40: =IF(B39="ITEM",A39,"") -> BABY CREMA ALOE W 80 BAG | N40: =IF(B37="MANUFACTURER",A37,N39) -> VigaLife | O40: =IF(B38="BRAND",A38,O39) -> BABY CREMA (VigaLife) | P40: =IF(B39="ITEM",N40,"") -> VigaLife | R40: =IF(B39="ITEM",O40,"") -> BABY CREMA (VigaLife) | T40: BABY CREMA ALOE W 80 BAG | U40: =IF(B39="ITEM",C39,"") -> BAGS | V40: =IF(B39="ITEM",D39,"") -> WITHOUT EXTRA PROTECTCARE INDICATION | W40: =IF(B39="ITEM",E39,"") -> 80 | X40: =IF(B39 = "ITEM",F39,"") -> 1.7698 | Y40: =IF(B39="ITEM",G39,"") -> 0.3617 | Z40: =IF(B39="ITEM",H39,"") -> 0.2081 | AA40: =IF(B39="ITEM",I39,"") -> 50.2205 | AB40: =IF(B39="ITEM",J39,"") -> 12.0681 | AC40: =IF(B39="ITEM",K39,"") -> 5.4643
...

Sheet Pivot Table
A3: Row Labels | B3: Sum of Value(1000$) 2022 | C3: Sum of Value(1000$) 2023 | D3: Sum of Value(1000$) 2024 | E3: Sum of Volume(1000) 2022 | F3: Sum of Volume(1000) 2023 | G3: Sum of Volume(1000) 2024 | H3: Sum of Average Price(2022) | I3: Sum of Average Price(2023) | J3: Sum of Average Price(2024) | K3: Sum of sum of value 22-24 | L3: Sum of sum of value 22-242 | M3: Sum of sum of value 22-243 | N3: YoY Value 2022-23 | O3: YoY Volume 2022-23 | P3: YoY Average Value 2022-23 | R3: YEAR | S3: 2022 | T3: 2023 | U3: 2024 | W3: difference in number(22-23) | X3: yoy difference in percenatge(22-23) | Y3: difference in number(23-24) | Z3: yoy difference in percenatge(23-24)
A4: VigaLife | B4: 3341.5013 | C4: 3428.0433 | D4: 1852.1966 | E4: 125970.25 | F4: 127615.61 | G4: 64977.618 | H4: 0.99167134 | I4: 0.83817512 | J4: 0.8399866 | K4: 8621.7412 | L4: 318563.48 | M4: 0.88994435 | N4: =IFERROR((C4/B4)-1,0) -> 0.025899137 | O4: =IFERROR((F4/E4)-1,0) -> 0.013061531 | P4: =IFERROR((I4/H4)-1,0) -> -0.15478537 | R4: Total Value | S4: =SUM(B4:B110) -> 11880.159 | T4: =SUM(C4:C110) -> 12264.847 | U4: =SUM(D4:D110) -> 6590.0513 | V4: Value | W4: =T4-S4 -> 384.6885 | X4: =IFERROR(((T4-S4)/T4),0) -> 0.031365127 | Y4: =U4-T4 -> -5674.7961 | Z4: =IFERROR(((U4-T4)/T4),0) -> -0.46268787
A5: Proctor & Wager | B5: 1818.5406 | C5: 2101.7048 | D5: 1233.5608 | E5: 45983.129 | F5: 53803.278 | G5: 29897.358 | H5: 4.6613627 | I5: 3.3633867 | J5: 1.7329292 | K5: 5153.8062 | L5: 129683.77 | M5: 3.2525595 | N5: =IFERROR((C5/B5)-1,0) -> 0.15570958 | O5: =IFERROR((F5/E5)-1,0) -> 0.17006562 | P5: =IFERROR((I5/H5)-1,0) -> -0.2784542 | R5: Total Volume | S5: =SUM(E4:E110) -> 470248.16 | T5: =SUM(F4:F110) -> 475047.06 | U5: =SUM(G4:G110) -> 239949.4 | V5: Volume | W5: =T5-S5 -> 4798.8996 | X5: =IFERROR(((T5-S5)/T5),0) -> 0.010101946 | Y5: =U5-T5 -> -235097.66 | Z5: =IFERROR(((U5-T5)/T5),0) -> -0.49489341
A6: Fulya Beauty | B6: 1012.923 | C6: 822.9812 | D6: 367.9878 | E6: 57405.587 | F6: 44546.772 | G6: 18766.233 | H6: 0.37077166 | I6: 0.40427677 | J6: 0.44246364 | K6: 2203.892 | L6: 120718.59 | M6: 0.40583736 | N6: =IFERROR((C6/B6)-1,0) -> -0.1875185 | O6: =IFERROR((F6/E6)-1,0) -> -0.22399937 | P6: =IFERROR((I6/H6)-1,0) -> 0.09036588 | R6: Average Price | S6: =IFERROR(S4/S5,0) -> 0.025263595 | T6: =IFERROR(T4/T5,0) -> 0.025818173 | U6: =IFERROR(U4/U5,0) -> 0.027464338 | V6: Average Prices | W6: =T6-S6 -> 0.00055457884 | X6: =IFERROR(((T6-S6)/T6),0) -> 0.021480173 | Y6: =U6-T6 -> 0.0016461641 | Z6: =IFERROR(((U6-T6)/T6),0) -> 0.0637599
A7: SepaTextiles | B7: 632.962 | C7: 529.4108 | D7: 262.1373 | E7: 36136.764 | F7: 28913.012 | G7: 13646.294 | H7: 0.21332748 | I7: 0.1980046 | J7: 0.1650894 | K7: 1424.5101 | L7: 78696.07 | M7: 0.19214049 | N7: =IFERROR((C7/B7)-1,0) -> -0.16359781 | O7: =IFERROR((F7/E7)-1,0) -> -0.19990036 | P7: =IFERROR((I7/H7)-1,0) -> -0.071827927
A8: Intelligent Initiative | B8: 511.7809 | C8: 507.3046 | D8: 295.7135 | E8: 23199.702 | F8: 21680.539 | G8: 11434.484 | H8: 0.26853896 | I8: 0.31561664 | J8: 0.34844293 | K8: 1314.799 | L8: 56314.725 | M8: 0.31086618 | N8: =IFERROR((C8/B8)-1,0) -> -0.0087465163 | O8: =IFERROR((F8/E8)-1,0) -> -0.065482017 | P8: =IFERROR((I8/H8)-1,0) -> 0.17531044
A9: AxisOn Group | B9: 471.6444 | C9: 448.0014 | D9: 276.1402 | E9: 13724.156 | F9: 13181.351 | G9: 8823.524 | H9: 0.42840833 | I9: 0.42837005 | J9: 0.35372089 | K9: 1195.786 | L9: 35729.032 | M9: 0.40349976 | N9: =IFERROR((C9/B9)-1,0) -> -0.050128868 | O9: =IFERROR((F9/E9)-1,0) -> -0.039551072 | P9: =IFERROR((I9/H9)-1,0) -> -8.9346712e-05
A10: Lara Beauty | B10: 394.6837 | C10: 409.4967 | D10: 321.2635 | E10: 18974.913 | F10: 19732.122 | G10: 15809.17 | H10: 0.60383046 | I10: 0.67133093 | J10: 0.6803564 | K10: 1125.4439 | L10: 54516.206 | M10: 0.65183926 | N10: =IFERROR((C10/B10)-1,0) -> 0.037531319 | O10: =IFERROR((F10/E10)-1,0) -> 0.0399058 | P10: =IFERROR((I10/H10)-1,0) -> 0.11178713
A11: LifeChem | B11: 332.0166 | C11: 406.0936 | D11: 185.5048 | E11: 9811.9589 | F11: 12002.149 | G11: 5143.8027 | H11: 0.234688 | I11: 0.16843793 | J11: 0.14433615 | K11: 923.615 | L11: 26957.911 | M11: 0.18248736 | N11: =IFERROR((C11/B11)-1,0) -> 0.22311234 | O11: =IFERROR((F11/E11)-1,0) -> 0.22321639 | P11: =IFERROR((I11/H11)-1,0) -> -0.28228998
A12: LovelyCo | B12: 466.3151 | C12: 321.9938 | D12: 119.9309 | E12: 27928.057 | F12: 19049.502 | G12: 6464.4499 | H12: 0.20476726 | I12: 0.22479619 | J12: 0.16924243 | K12: 908.2398 | L12: 53442.009 | M12: 0.19960196 | N12: =IFERROR((C12/B12)-1,0) -> -0.30949309 | O12: =IFERROR((F12/E12)-1,0) -> -0.31790806 | P12: =IFERROR((I12/H12)-1,0) -> 0.097813121
A13: Giga S.A. | B13: 336.5157 | C13: 318.6227 | D13: 125.7655 | E13: 10227.005 | F13: 9928.9133 | G13: 3640.5187 | H13: 0.51165192 | I13: 0.41377931 | J13: 0.38910625 | K13: 780.9039 | L13: 23796.437 | M13: 0.43817916 | N13: =IFERROR((C13/B13)-1,0) -> -0.053171368 | O13: =IFERROR((F13/E13)-1,0) -> -0.029147554 | P13: =IFERROR((I13/H13)-1,0) -> -0.19128748
A14: CleanHarper | B14: 230.7483 | C14: 302.0658 | D14: 144.0024 | E14: 11792.665 | F14: 15544.818 | G14: 7126.6585 | H14: 0.03860304 | I14: 0.3220751 | J14: 0.31659002 | K14: 676.8165 | L14: 34464.142 | M14: 0.22575605 | N14: =IFERROR((C14/B14)-1,0) -> 0.30907053 | O14: =IFERROR((F14/E14)-1,0) -> 0.31817678 | P14: =IFERROR((I14/H14)-1,0) -> 7.3432572
A15: CelticWind Ltd | B15: 220.2778 | C15: 271.9984 | D15: 141.2388 | E15: 1748.9224 | F15: 2358.5312 | G15: 1240.7413 | H15: 0.70351841 | I15: 0.65978193 | J15: 0.68063185 | K15: 633.515 | L15: 5348.1949 | M15: 0.68131073 | N15: =IFERROR((C15/B15)-1,0) -> 0.23479715 | O15: =IFERROR((F15/E15)-1,0) -> 0.34856252 | P15: =IFERROR((I15/H15)-1,0) -> -0.062168217
A16: ProStart 97 | B16: 192.723 | C16: 183.2434 | D16: 97.2096 | E16: 7900.9691 | F16: 6838.8454 | G16: 3264.5806 | H16: 0.024392324 | I16: 0.026794494 | J16: 0.029777056 | K16: 473.176 | L16: 18004.395 | M16: 0.026987958 | N16: =IFERROR((C16/B16)-1,0) -> -0.049187694 | O16: =IFERROR((F16/E16)-1,0) -> -0.13442955 | P16: =IFERROR((I16/H16)-1,0) -> 0.098480549
A17: Kimberly Stone | B17: 168.5793 | C17: 187.8254 | D17: 100.9209 | E17: 4051.7897 | F17: 4420.8852 | G17: 2421.1073 | H17: 0.2484275 | I17: 0.20654952 | J17: 0.20987569 | K17: 457.3256 | L17: 10893.782 | M17: 0.22161757 | N17: =IFERROR((C17/B17)-1,0) -> 0.11416645 | O17: =IFERROR((F17/E17)-1,0) -> 0.091094437 | P17: =IFERROR((I17/H17)-1,0) -> -0.16857224
A18: Voyage Turkey | B18: 131.4905 | C18: 246.0711 | D18: 78.1818 | E18: 7528.2014 | F18: 14073.58 | G18: 4344.6674 | H18: 0.20668171 | I18: 0.14280447 | J18: 0.11116954 | K18: 455.7434 | L18: 25946.449 | M18: 0.15355191 | N18: =IFERROR((C18/B18)-1,0) -> 0.87139831 | O18: =IFERROR((F18/E18)-1,0) -> 0.86944787 | P18: =IFERROR((I18/H18)-1,0) -> -0.30906091
... A111: Grand Total | B111: 11880.159 | C111: 12264.847 | D111: 6590.0513 | E111: 470248.16 | F111: 475047.06 | G111: 239949.4 | H111: 18.113785 | I111: 16.276822 | J111: 13.314822 | K111: 30735.058 | L111: 1185244.6 | M111: 15.90181 | N111: =IFERROR((C111/B111)-1,0) -> 0.032380754 | O111: =IFERROR((F111/E111)-1,0) -> 0.010205036 | P111: =IFERROR((I111/H111)-1,0) -> -0.10141242

Sheet cleaned data
A1: Product | B1: Manufacturer | C1: Brand | D1: Package Type | E1: Protection | F1: Package Size | G1: Value(1000$) 2022 | H1: Value(1000$) 2023 | I1: Value(1000$) 2024 | J1: Volume(1000) 2022 | K1: Volume(1000) 2023 | L1: Volume(1000) 2024 | M1: Average Price(2022) | N1: Average Price(2023) | O1: Average Price(2024) | P1: sum of value 22-24 | Q1: sum of value 22-242 | R1: sum of value 22-243
A2: BABY2000 CAMOMILLA W 20 BAG ABA SRL | B2: Nova Garbagnate | C2: BABY 2000 (Nova Garbagnate) | D2: BAGS | E2: WITHOUT EXTRA PROTECTCARE INDICATION | F2: =IF('Working Sheet'!B6="ITEM",'Working Sheet'!E6,"") -> 20 | G2: =IF('Working Sheet'!B6="ITEM",'Working Sheet'!F6,"") -> 1.935 | H2: =IF('Working Sheet'!B6="ITEM",'Working Sheet'!G6,"") -> 0.624 | I2: =IF('Working Sheet'!B6="ITEM",'Working Sheet'!H6,"") -> 0 | J2: =IF('Working Sheet'!B6="ITEM",'Working Sheet'!I6,"") -> 24.8229 | K2: =IF('Working Sheet'!B6="ITEM",'Working Sheet'!J6,"") -> 9.4086 | L2: =IF('Working Sheet'!B6="ITEM",'Working Sheet'!K6,"") -> 0 | M2: =IFERROR(Table2[[#This Row],[Value(1000$) 2022]]/Table2[[#This Row],[Volume(1000) 2022]],0) -> 0.077952213 | N2: =IFERROR(Table2[[#This Row],[Value(1000$) 2023]]/Table2[[#This Row],[Volume(1000) 2023]],0) -> 0.066322301 | O2: =IFERROR(Table2[[#This Row],[Value(1000$) 2024]]/Table2[[#This Row],[Volume(1000) 2024]],0) -> 0 | P2: =SUM(Table2[[#This Row],[Value(1000$) 2022]:[Value(1000$) 2024]]) -> 2.559 | Q2: =SUM(Table2[[#This Row],[Volume(1000) 2022]:[Volume(1000) 2024]]) -> 34.2315 | R2: =AVERAGE(Table2[[#This Row],[Average Price(2022)]:[Average Price(2024)]]) -> 0.048091505
A3: BAMBO NATURE W 10 BAG | B3: BeneCare | C3: BAMBO (BeneCare) | D3: BAGS | E3: WITHOUT EXTRA PROTECTCARE INDICATION | F3: =IF('Working Sheet'!B9="ITEM",'Working Sheet'!E9,"") -> 10 | G3: =IF('Working Sheet'!B9="ITEM",'Working Sheet'!F9,"") -> 0 | H3: =IF('Working Sheet'!B9="ITEM",'Working Sheet'!G9,"") -> 0 | I3: =IF('Working Sheet'!B9="ITEM",'Working Sheet'!H9,"") -> 0 | J3: =IF('Working Sheet'!B9="ITEM",'Working Sheet'!I9,"") -> 0 | K3: =IF('Working Sheet'!B9="ITEM",'Working Sheet'!J9,"") -> 0 | L3: =IF('Working Sheet'!B9="ITEM",'Working Sheet'!K9,"") -> 0 | M3: =IFERROR(Table2[[#This Row],[Value(1000$) 2022]]/Table2[[#This Row],[Volume(1000) 2022]],0) -> 0 | N3: =IFERROR(Table2[[#This Row],[Value(1000$) 2023]]/Table2[[#This Row],[Volume(1000) 2023]],0) -> 0 | O3: =IFERROR(Table2[[#This Row],[Value(1000$) 2024]]/Table2[[#This Row],[Volume(1000) 2024]],0) -> 0 | P3: =SUM(Table2[[#This Row],[Value(1000$) 2022]:[Value(1000$) 2024]]) -> 0 | Q3: =SUM(Table2[[#This Row],[Volume(1000) 2022]:[Volume(1000) 2024]]) -> 0 | R3: =AVERAGE(Table2[[#This Row],[Average Price(2022)]:[Average Price(2024)]]) -> 0
A4: BAMBO NATURE W 50 BAG | B4: BeneCare | C4: BAMBO (BeneCare) | D4: BAGS | E4: WITHOUT EXTRA PROTECTCARE INDICATION | F4: =IF('Working Sheet'!B10="ITEM",'Working Sheet'!E10,"") -> 50 | G4: =IF('Working Sheet'!B10="ITEM",'Working Sheet'!F10,"") -> 0 | H4: =IF('Working Sheet'!B10="ITEM",'Working Sheet'!G10,"") -> 0 | I4: =IF('Working Sheet'!B10="ITEM",'Working Sheet'!H10,"") -> 0 | J4: =IF('Working Sheet'!B10="ITEM",'Working Sheet'!I10,"") -> 0 | K4: =IF('Working Sheet'!B10="ITEM",'Working Sheet'!J10,"") -> 0 | L4: =IF('Working Sheet'!B10="ITEM",'Working Sheet'!K10,"") -> 0 | M4: =IFERROR(Table2[[#This Row],[Value(1000$) 2022]]/Table2[[#This Row],[Volume(1000) 2022]],0) -> 0 | N4: =IFERROR(Table2[[#This Row],[Value(1000$) 2023]]/Table2[[#This Row],[Volume(1000) 2023]],0) -> 0 | O4: =IFERROR(Table2[[#This Row],[Value(1000$) 2024]]/Table2[[#This Row],[Volume(1000) 2024]],0) -> 0 | P4: =SUM(Table2[[#This Row],[Value(1000$) 2022]:[Value(1000$) 2024]]) -> 0 | Q4: =SUM(Table2[[#This Row],[Volume(1000) 2022]:[Volume(1000) 2024]]) -> 0 | R4: =AVERAGE(Table2[[#This Row],[Average Price(2022)]:[Average Price(2024)]]) -> 0
A5: BAMBO NATURE 0%PERFUME W 80 BAG | B5: BeneCare | C5: BAMBO (BeneCare) | D5: BAGS | E5: WITHOUT EXTRA PROTECTCARE INDICATION | F5: =IF('Working Sheet'!B11="ITEM",'Working Sheet'!E11,"") -> 80 | G5: =IF('Working Sheet'!B11="ITEM",'Working Sheet'!F11,"") -> 0 | H5: =IF('Working Sheet'!B11="ITEM",'Working Sheet'!G11,"") -> 0 | I5: =IF('Working Sheet'!B11="ITEM",'Working Sheet'!H11,"") -> 0 | J5: =IF('Working Sheet'!B11="ITEM",'Working Sheet'!I11,"") -> 0 | K5: =IF('Working Sheet'!B11="ITEM",'Working Sheet'!J11,"") -> 0 | L5: =IF('Working Sheet'!B11="ITEM",'Working Sheet'!K11,"") -> 0 | M5: =IFERROR(Table2[[#This Row],[Value(1000$) 2022]]/Table2[[#This Row],[Volume(1000) 2022]],0) -> 0 | N5: =IFERROR(Table2[[#This Row],[Value(1000$) 2023]]/Table2[[#This Row],[Volume(1000) 2023]],0) -> 0 | O5: =IFERROR(Table2[[#This Row],[Value(1000$) 2024]]/Table2[[#This Row],[Volume(1000) 2024]],0) -> 0 | P5: =SUM(Table2[[#This Row],[Value(1000$) 2022]:[Value(1000$) 2024]]) -> 0 | Q5: =SUM(Table2[[#This Row],[Volume(1000) 2022]:[Volume(1000) 2024]]) -> 0 | R5: =AVERAGE(Table2[[#This Row],[Average Price(2022)]:[Average Price(2024)]]) -> 0
A6: BAMBO NATURE W 80 BAG KAPAK | B6: BeneCare | C6: BAMBO (BeneCare) | D6: BAGS | E6: WITHOUT EXTRA PROTECTCARE INDICATION | F6: =IF('Working Sheet'!B12="ITEM",'Working Sheet'!E12,"") -> 80 | G6: =IF('Working Sheet'!B12="ITEM",'Working Sheet'!F12,"") -> 0.0109 | H6: =IF('Working Sheet'!B12="ITEM",'Working Sheet'!G12,"") -> 0 | I6: =IF('Working Sheet'!B12="ITEM",'Working Sheet'!H12,"") -> 0 | J6: =IF('Working Sheet'!B12="ITEM",'Working Sheet'!I12,"") -> 0.16 | K6: =IF('Working Sheet'!B12="ITEM",'Working Sheet'!J12,"") -> 0 | L6: =IF('Working Sheet'!B12="ITEM",'Working Sheet'!K12,"") -> 0 | M6: =IFERROR(Table2[[#This Row],[Value(1000$) 2022]]/Table2[[#This Row],[Volume(1000) 2022]],0) -> 0.068125 | N6: =IFERROR(Table2[[#This Row],[Value(1000$) 2023]]/Table2[[#This Row],[Volume(1000) 2023]],0) -> 0 | O6: =IFERROR(Table2[[#This Row],[Value(1000$) 2024]]/Table2[[#This Row],[Volume(1000) 2024]],0) -> 0 | P6: =SUM(Table2[[#This Row],[Value(1000$) 2022]:[Value(1000$) 2024]]) -> 0.0109 | Q6: =SUM(Table2[[#This Row],[Volume(1000) 2022]:[Volume(1000) 2024]]) -> 0.16 | R6: =AVERAGE(Table2[[#This Row],[Average Price(2022)]:[Average Price(2024)]]) -> 0.022708333
A7: BABY CREMA PLAY TIME CAMOMILE W 100 PINK | B7: VigaLife | C7: BABY CREMA (VigaLife) | D7: BAGS | E7: PH BALANCED | F7: =IF('Working Sheet'!B15="ITEM",'Working Sheet'!E15,"") -> 100 | G7: =IF('Working Sheet'!B15="ITEM",'Working Sheet'!F15,"") -> 81.4674 | H7: =IF('Working Sheet'!B15="ITEM",'Working Sheet'!G15,"") -> 92.903 | I7: =IF('Working Sheet'!B15="ITEM",'Working Sheet'!H15,"") -> 52.5119 | J7: =IF('Working Sheet'!B15="ITEM",'Working Sheet'!I15,"") -> 2980.7043 | K7: =IF('Working Sheet'!B15="ITEM",'Working Sheet'!J15,"") -> 3415.3554 | L7: =IF('Working Sheet'!B15="ITEM",'Working Sheet'!K15,"") -> 1823.0734 | M7: =IFERROR(Table2[[#This Row],[Value(1000$) 2022]]/Table2[[#This Row],[Volume(1000) 2022]],0) -> 0.027331594 | N7: =IFERROR(Table2[[#This Row],[Value(1000$) 2023]]/Table2[[#This Row],[Volume(1000) 2023]],0) -> 0.027201562 | O7: =IFERROR(Table2[[#This Row],[Value(1000$) 2024]]/Table2[[#This Row],[Volume(1000) 2024]],0) -> 0.028804051 | P7: =SUM(Table2[[#This Row],[Value(1000$) 2022]:[Value(1000$) 2024]]) -> 226.8823 | Q7: =SUM(Table2[[#This Row],[Volume(1000) 2022]:[Volume(1000) 2024]]) -> 8219.1331 | R7: =AVERAGE(Table2[[#This Row],[Average Price(2022)]:[Average Price(2024)]]) -> 0.027779069
A8: BABYCREMA PLAYTIME CAMOMILE W 100 ORANGE | B8: VigaLife | C8: BABY CREMA (VigaLife) | D8: BAGS | E8: PH BALANCED | F8: =IF('Working Sheet'!B16="ITEM",'Working Sheet'!E16,"") -> 100 | G8: =IF('Working Sheet'!B16="ITEM",'Working Sheet'!F16,"") -> 165.228 | H8: =IF('Working Sheet'!B16="ITEM",'Working Sheet'!G16,"") -> 172.6843 | I8: =IF('Working Sheet'!B16="ITEM",'Working Sheet'!H16,"") -> 91.1357 | J8: =IF('Working Sheet'!B16="ITEM",'Working Sheet'!I16,"") -> 5930.9056 | K8: =IF('Working Sheet'!B16="ITEM",'Working Sheet'!J16,"") -> 6183.6273 | L8: =IF('Working Sheet'!B16="ITEM",'Working Sheet'!K16,"") -> 3125.7987 | M8: =IFERROR(Table2[[#This Row],[Value(1000$) 2022]]/Table2[[#This Row],[Volume(1000) 2022]],0) -> 0.027858815 | N8: =IFERROR(Table2[[#This Row],[Value(1000$) 2023]]/Table2[[#This Row],[Volume(1000) 2023]],0) -> 0.027926052 | O8: =IFERROR(Table2[[#This Row],[Value(1000$) 2024]]/Table2[[#This Row],[Volume(1000) 2024]],0) -> 0.029155972 | P8: =SUM(Table2[[#This Row],[Value(1000$) 2022]:[Value(1000$) 2024]]) -> 429.048 | Q8: =SUM(Table2[[#This Row],[Volume(1000) 2022]:[Volume(1000) 2024]]) -> 15240.332 | R8: =AVERAGE(Table2[[#This Row],[Average Price(2022)]:[Average Price(2024)]]) -> 0.028313613
A9: BABY CREMA CAMOMIL W 120 BAG KAPAK | B9: VigaLife | C9: BABY CREMA (VigaLife) | D9: BAGS | E9: PH BALANCED | F9: =IF('Working Sheet'!B17="ITEM",'Working Sheet'!E17,"") -> 120 | G9: =IF('Working Sheet'!B17="ITEM",'Working Sheet'!F17,"") -> 842.8724 | H9: =IF('Working Sheet'!B17="ITEM",'Working Sheet'!G17,"") -> 745.3358 | I9: =IF('Working Sheet'!B17="ITEM",'Working Sheet'!H17,"") -> 366.9589 | J9: =IF('Working Sheet'!B17="ITEM",'Working Sheet'!I17,"") -> 38888.54 | K9: =IF('Working Sheet'!B17="ITEM",'Working Sheet'!J17,"") -> 31985 | L9: =IF('Working Sheet'!B17="ITEM",'Working Sheet'!K17,"") -> 14135.173 | M9: =IFERROR(Table2[[#This Row],[Value(1000$) 2022]]/Table2[[#This Row],[Volume(1000) 2022]],0) -> 0.021674056 | N9: =IFERROR(Table2[[#This Row],[Value(1000$) 2023]]/Table2[[#This Row],[Volume(1000) 2023]],0) -> 0.023302667 | O9: =IFERROR(Table2[[#This Row],[Value(1000$) 2024]]/Table2[[#This Row],[Volume(1000) 2024]],0) -> 0.025960694 | P9: =SUM(Table2[[#This Row],[Value(1000$) 2022]:[Value(1000$) 2024]]) -> 1955.1671 | Q9: =SUM(Table2[[#This Row],[Volume(1000) 2022]:[Volume(1000) 2024]]) -> 85008.713 | R9: =AVERAGE(Table2[[#This Row],[Average Price(2022)]:[Average Price(2024)]]) -> 0.023645806
A10: BABY CREMA ALOE 15 BAG | B10: VigaLife | C10: BABY CREMA (VigaLife) | D10: BAGS | E10: WITHOUT EXTRA PROTECTCARE INDICATION | F10: =IF('Working Sheet'!B18="ITEM",'Working Sheet'!E18,"") -> 15 | G10: =IF('Working Sheet'!B18="ITEM",'Working Sheet'!F18,"") -> 12.7748 | H10: =IF('Working Sheet'!B18="ITEM",'Working Sheet'!G18,"") -> 10.866 | I10: =IF('Working Sheet'!B18="ITEM",'Working Sheet'!H18,"") -> 6.7743 | J10: =IF('Working Sheet'!B18="ITEM",'Working Sheet'!I18,"") -> 151.2668 | K10: =IF('Working Sheet'!B18="ITEM",'Working Sheet'!J18,"") -> 127.1868 | L10: =IF('Working Sheet'!B18="ITEM",'Working Sheet'!K18,"") -> 77.4594 | M10: =IFERROR(Table2[[#This Row],[Value(1000$) 2022]]/Table2[[#This Row],[Volume(1000) 2022]],0) -> 0.084452107 | N10: =IFERROR(Table2[[#This Row],[Value(1000$) 2023]]/Table2[[#This Row],[Volume(1000) 2023]],0) -> 0.085433394 | O10: =IFERROR(Table2[[#This Row],[Value(1000$) 2024]]/Table2[[#This Row],[Volume(1000) 2024]],0) -> 0.087456138 | P10: =SUM(Table2[[#This Row],[Value(1000$) 2022]:[Value(1000$) 2024]]) -> 30.4151 | Q10: =SUM(Table2[[#This Row],[Volume(1000) 2022]:[Volume(1000) 2024]]) -> 355.913 | R10: =AVERAGE(Table2[[#This Row],[Average Price(2022)]:[Average Price(2024)]]) -> 0.085780546
A11: BABY CREMA CAMOMIL W 15 BAG | B11: VigaLife | C11: BABY CREMA (VigaLife) | D11: BAGS | E11: WITHOUT EXTRA PROTECTCARE INDICATION | F11: =IF('Working Sheet'!B19="ITEM",'Working Sheet'!E19,"") -> 15 | G11: =IF('Working Sheet'!B19="ITEM",'Working Sheet'!F19,"") -> 20.0553 | H11: =IF('Working Sheet'!B19="ITEM",'Working Sheet'!G19,"") -> 17.8361 | I11: =IF('Working Sheet'!B19="ITEM",'Working Sheet'!H19,"") -> 11.1871 | J11: =IF('Working Sheet'!B19="ITEM",'Working Sheet'!I19,"") -> 231.0878 | K11: =IF('Working Sheet'!B19="ITEM",'Working Sheet'!J19,"") -> 217.7118 | L11: =IF('Working Sheet'!B19="ITEM",'Working Sheet'!K19,"") -> 141.008 | M11: =IFERROR(Table2[[#This Row],[Value(1000$) 2022]]/Table2[[#This Row],[Volume(1000) 2022]],0) -> 0.086786494 | N11: =IFERROR(Table2[[#This Row],[Value(1000$) 2023]]/Table2[[#This Row],[Volume(1000) 2023]],0) -> 0.081925279 | O11: =IFERROR(Table2[[#This Row],[Value(1000$) 2024]]/Table2[[#This Row],[Volume(1000) 2024]],0) -> 0.079336633 | P11: =SUM(Table2[[#This Row],[Value(1000$) 2022]:[Value(1000$) 2024]]) -> 49.0785 | Q11: =SUM(Table2[[#This Row],[Volume(1000) 2022]:[Volume(1000) 2024]]) -> 589.8076 | R11: =AVERAGE(Table2[[#This Row],[Average Price(2022)]:[Average Price(2024)]]) -> 0.082682802
A12: BABY CREMA PH5.5 W 3X15/1FR BAG &&& | B12: VigaLife | C12: BABY CREMA (VigaLife) | D12: BAGS | E12: PH BALANCED | F12: =IF('Working Sheet'!B20="ITEM",'Working Sheet'!E20,"") -> 15 | G12: =IF('Working Sheet'!B20="ITEM",'Working Sheet'!F20,"") -> 1.2461 | H12: =IF('Working Sheet'!B20="ITEM",'Working Sheet'!G20,"") -> 7.7651 | I12: =IF('Working Sheet'!B20="ITEM",'Working Sheet'!H20,"") -> 2.2378 | J12: =IF('Working Sheet'!B20="ITEM",'Working Sheet'!I20,"") -> 20.9609 | K12: =IF('Working Sheet'!B20="ITEM",'Working Sheet'!J20,"") -> 127.6666 | L12: =IF('Working Sheet'!B20="ITEM",'Working Sheet'!K20,"") -> 33.571 | M12: =IFERROR(Table2[[#This Row],[Value(1000$) 2022]]/Table2[[#This Row],[Volume(1000) 2022]],0) -> 0.059448783 | N12: =IFERROR(Table2[[#This Row],[Value(1000$) 2023]]/Table2[[#This Row],[Volume(1000) 2023]],0) -> 0.060823269 | O12: =IFERROR(Table2[[#This Row],[Value(1000$) 2024]]/Table2[[#This Row],[Volume(1000) 2024]],0) -> 0.066658723 | P12: =SUM(Table2[[#This Row],[Value(1000$) 2022]:[Value(1000$) 2024]]) -> 11.249 | Q12: =SUM(Table2[[#This Row],[Volume(1000) 2022]:[Volume(1000) 2024]]) -> 182.1985 | R12: =AVERAGE(Table2[[#This Row],[Average Price(2022)]:[Average Price(2024)]]) -> 0.062310259
A13: BABY CREMA WATER 99% W 15 BAG | B13: VigaLife | C13: BABY CREMA (VigaLife) | D13: BAGS | E13: ALCOHOL FREE | F13: =IF('Working Sheet'!B21="ITEM",'Working Sheet'!E21,"") -> 15 | G13: =IF('Working Sheet'!B21="ITEM",'Working Sheet'!F21,"") -> 9.6472 | H13: =IF('Working Sheet'!B21="ITEM",'Working Sheet'!G21,"") -> 10.7577 | I13: =IF('Working Sheet'!B21="ITEM",'Working Sheet'!H21,"") -> 7.0723 | J13: =IF('Working Sheet'!B21="ITEM",'Working Sheet'!I21,"") -> 112.2061 | K13: =IF('Working Sheet'!B21="ITEM",'Working Sheet'!J21,"") -> 131.0528 | L13: =IF('Working Sheet'!B21="ITEM",'Working Sheet'!K21,"") -> 85.7198 | M13: =IFERROR(Table2[[#This Row],[Value(1000$) 2022]]/Table2[[#This Row],[Volume(1000) 2022]],0) -> 0.0859775 | N13: =IFERROR(Table2[[#This Row],[Value(1000$) 2023]]/Table2[[#This Row],[Volume(1000) 2023]],0) -> 0.082086762 | O13: =IFERROR(Table2[[#This Row],[Value(1000$) 2024]]/Table2[[#This Row],[Volume(1000) 2024]],0) -> 0.082504859 | P13: =SUM(Table2[[#This Row],[Value(1000$) 2022]:[Value(1000$) 2024]]) -> 27.4772 | Q13: =SUM(Table2[[#This Row],[Volume(1000) 2022]:[Volume(1000) 2024]]) -> 328.9787 | R13: =AVERAGE(Table2[[#This Row],[Average Price(2022)]:[Average Price(2024)]]) -> 0.08352304
A14: BABY CREMA CAMOMIL W 40 BAG | B14: VigaLife | C14: BABY CREMA (VigaLife) | D14: BAGS | E14: WITHOUT EXTRA PROTECTCARE INDICATION | F14: =IF('Working Sheet'!B22="ITEM",'Working Sheet'!E22,"") -> 40 | G14: =IF('Working Sheet'!B22="ITEM",'Working Sheet'!F22,"") -> 0.1235 | H14: =IF('Working Sheet'!B22="ITEM",'Working Sheet'!G22,"") -> 0 | I14: =IF('Working Sheet'!B22="ITEM",'Working Sheet'!H22,"") -> 0 | J14: =IF('Working Sheet'!B22="ITEM",'Working Sheet'!I22,"") -> 2.28 | K14: =IF('Working Sheet'!B22="ITEM",'Working Sheet'!J22,"") -> 0 | L14: =IF('Working Sheet'!B22="ITEM",'Working Sheet'!K22,"") -> 0 | M14: =IFERROR(Table2[[#This Row],[Value(1000$) 2022]]/Table2[[#This Row],[Volume(1000) 2022]],0) -> 0.054166667 | N14: =IFERROR(Table2[[#This Row],[Value(1000$) 2023]]/Table2[[#This Row],[Volume(1000) 2023]],0) -> 0 | O14: =IFERROR(Table2[[#This Row],[Value(1000$) 2024]]/Table2[[#This Row],[Volume(1000) 2024]],0) -> 0 | P14: =SUM(Table2[[#This Row],[Value(1000$) 2022]:[Value(1000$) 2024]]) -> 0.1235 | Q14: =SUM(Table2[[#This Row],[Volume(1000) 2022]:[Volume(1000) 2024]]) -> 2.28 | R14: =AVERAGE(Table2[[#This Row],[Average Price(2022)]:[Average Price(2024)]]) -> 0.018055556
A15: BABY CREMA COTTON&PANTENOL W 4X56 BAG | B15: VigaLife | C15: BABY CREMA (VigaLife) | D15: BAGS | E15: PH BALANCED | F15: =IF('Working Sheet'!B23="ITEM",'Working Sheet'!E23,"") -> 56 | G15: =IF('Working Sheet'!B23="ITEM",'Working Sheet'!F23,"") -> 0 | H15: =IF('Working Sheet'!B23="ITEM",'Working Sheet'!G23,"") -> 0 | I15: =IF('Working Sheet'!B23="ITEM",'Working Sheet'!H23,"") -> 7.1128 | J15: =IF('Working Sheet'!B23="ITEM",'Working Sheet'!I23,"") -> 0 | K15: =IF('Working Sheet'!B23="ITEM",'Working Sheet'!J23,"") -> 0 | L15: =IF('Working Sheet'!B23="ITEM",'Working Sheet'!K23,"") -> 247.099 | M15: =IFERROR(Table2[[#This Row],[Value(1000$) 2022]]/Table2[[#This Row],[Volume(1000) 2022]],0) -> 0 | N15: =IFERROR(Table2[[#This Row],[Value(1000$) 2023]]/Table2[[#This Row],[Volume(1000) 2023]],0) -> 0 | O15: =IFERROR(Table2[[#This Row],[Value(1000$) 2024]]/Table2[[#This Row],[Volume(1000) 2024]],0) -> 0.028785224 | P15: =SUM(Table2[[#This Row],[Value(1000$) 2022]:[Value(1000$) 2024]]) -> 7.1128 | Q15: =SUM(Table2[[#This Row],[Volume(1000) 2022]:[Volume(1000) 2024]]) -> 247.099 | R15: =AVERAGE(Table2[[#This Row],[Average Price(2022)]:[Average Price(2024)]]) -> 0.0095950746
A16: BABY CREMA COTTON&PANTENOL W 56 BAG | B16: VigaLife | C16: BABY CREMA (VigaLife) | D16: BAGS | E16: PH BALANCED | F16: =IF('Working Sheet'!B24="ITEM",'Working Sheet'!E24,"") -> 56 | G16: =IF('Working Sheet'!B24="ITEM",'Working Sheet'!F24,"") -> 0.1831 | H16: =IF('Working Sheet'!B24="ITEM",'Working Sheet'!G24,"") -> 0.1116 | I16: =IF('Working Sheet'!B24="ITEM",'Working Sheet'!H24,"") -> 0.387 | J16: =IF('Working Sheet'!B24="ITEM",'Working Sheet'!I24,"") -> 5.8885 | K16: =IF('Working Sheet'!B24="ITEM",'Working Sheet'!J24,"") -> 3.791 | L16: =IF('Working Sheet'!B24="ITEM",'Working Sheet'!K24,"") -> 14.3827 | M16: =IFERROR(Table2[[#This Row],[Value(1000$) 2022]]/Table2[[#This Row],[Volume(1000) 2022]],0) -> 0.031094506 | N16: =IFERROR(Table2[[#This Row],[Value(1000$) 2023]]/Table2[[#This Row],[Volume(1000) 2023]],0) -> 0.029438143 | O16: =IFERROR(Table2[[#This Row],[Value(1000$) 2024]]/Table2[[#This Row],[Volume(1000) 2024]],0) -> 0.026907326 | P16: =SUM(Table2[[#This Row],[Value(1000$) 2022]:[Value(1000$) 2024]]) -> 0.6817 | Q16: =SUM(Table2[[#This Row],[Volume(1000) 2022]:[Volume(1000) 2024]]) -> 24.0622 | R16: =AVERAGE(Table2[[#This Row],[Average Price(2022)]:[Average Price(2024)]]) -> 0.029146658
A17: BABY CREMA ALOE 64 BAG | B17: VigaLife | C17: BABY CREMA (VigaLife) | D17: BAGS | E17: WITHOUT EXTRA PROTECTCARE INDICATION | F17: =IF('Working Sheet'!B25="ITEM",'Working Sheet'!E25,"") -> 64 | G17: =IF('Working Sheet'!B25="ITEM",'Working Sheet'!F25,"") -> 1.8939 | H17: =IF('Working Sheet'!B25="ITEM",'Working Sheet'!G25,"") -> 0 | I17: =IF('Working Sheet'!B25="ITEM",'Working Sheet'!H25,"") -> 0.2252 | J17: =IF('Working Sheet'!B25="ITEM",'Working Sheet'!I25,"") -> 49.9726 | K17: =IF('Working Sheet'!B25="ITEM",'Working Sheet'!J25,"") -> 0 | L17: =IF('Working Sheet'!B25="ITEM",'Working Sheet'!K25,"") -> 6.9501 | M17: =IFERROR(Table2[[#This Row],[Value(1000$) 2022]]/Table2[[#This Row],[Volume(1000) 2022]],0) -> 0.037898769 | N17: =IFERROR(Table2[[#This Row],[Value(1000$) 2023]]/Table2[[#This Row],[Volume(1000) 2023]],0) -> 0 | O17: =IFERROR(Table2[[#This Row],[Value(1000$) 2024]]/Table2[[#This Row],[Volume(1000) 2024]],0) -> 0.032402411 | P17: =SUM(Table2[[#This Row],[Value(1000$) 2022]:[Value(1000$) 2024]]) -> 2.1191 | Q17: =SUM(Table2[[#This Row],[Volume(1000) 2022]:[Volume(1000) 2024]]) -> 56.9227 | R17: =AVERAGE(Table2[[#This Row],[Average Price(2022)]:[Average Price(2024)]]) -> 0.023433727
A18: BABY CREMA CAMOMIL W 64 BAG | B18: VigaLife | C18: BABY CREMA (VigaLife) | D18: BAGS | E18: WITHOUT EXTRA PROTECTCARE INDICATION | F18: =IF('Working Sheet'!B26="ITEM",'Working Sheet'!E26,"") -> 64 | G18: =IF('Working Sheet'!B26="ITEM",'Working Sheet'!F26,"") -> 1.3515 | H18: =IF('Working Sheet'!B26="ITEM",'Working Sheet'!G26,"") -> 0.0017 | I18: =IF('Working Sheet'!B26="ITEM",'Working Sheet'!H26,"") -> 0 | J18: =IF('Working Sheet'!B26="ITEM",'Working Sheet'!I26,"") -> 37.3226 | K18: =IF('Working Sheet'!B26="ITEM",'Working Sheet'!J26,"") -> 0.064 | L18: =IF('Working Sheet'!B26="ITEM",'Working Sheet'!K26,"") -> 0 | M18: =IFERROR(Table2[[#This Row],[Value(1000$) 2022]]/Table2[[#This Row],[Volume(1000) 2022]],0) -> 0.036211304 | N18: =IFERROR(Table2[[#This Row],[Value(1000$) 2023]]/Table2[[#This Row],[Volume(1000) 2023]],0) -> 0.0265625 | O18: =IFERROR(Table2[[#This Row],[Value(1000$) 2024]]/Table2[[#This Row],[Volume(1000) 2024]],0) -> 0 | P18: =SUM(Table2[[#This Row],[Value(1000$) 2022]:[Value(1000$) 2024]]) -> 1.3532 | Q18: =SUM(Table2[[#This Row],[Volume(1000) 2022]:[Volume(1000) 2024]]) -> 37.3866 | R18: =AVERAGE(Table2[[#This Row],[Average Price(2022)]:[Average Price(2024)]]) -> 0.020924601
... A32: BABY CREMA CAMOMIL W 80 BAG | B32: VigaLife | C32: BABY CREMA (VigaLife) | D32: BAGS | E32: WITHOUT EXTRA PROTECTCARE INDICATION | F32: =IF('Working Sheet'!B40="ITEM",'Working Sheet'!E40,"") -> 80 | G32: =IF('Working Sheet'!B40="ITEM",'Working Sheet'!F40,"") -> 61.9819 | H32: =IF('Working Sheet'!B40="ITEM",'Working Sheet'!G40,"") -> 56.9702 | I32: =IF('Working Sheet'!B40="ITEM",'Working Sheet'!H40,"") -> 23.8948 | J32: =IF('Working Sheet'!B40="ITEM",'Working Sheet'!I40,"") -> 1524.2099 | K32: =IF('Working Sheet'!B40="ITEM",'Working Sheet'!J40,"") -> 1404.4859 | L32: =IF('Working Sheet'!B40="ITEM",'Working Sheet'!K40,"") -> 554.6842 | M32: =IFERROR(Table2[[#This Row],[Value(1000$) 2022]]/Table2[[#This Row],[Volume(1000) 2022]],0) -> 0.040664937 | N32: =IFERROR(Table2[[#This Row],[Value(1000$) 2023]]/Table2[[#This Row],[Volume(1000) 2023]],0) -> 0.040563027 | O32: =IFERROR(Table2[[#This Row],[Value(1000$) 2024]]/Table2[[#This Row],[Volume(1000) 2024]],0) -> 0.043078206 | P32: =SUM(Table2[[#This Row],[Value(1000$) 2022]:[Value(1000$) 2024]]) -> 142.8469 | Q32: =SUM(Table2[[#This Row],[Volume(1000) 2022]:[Volume(1000) 2024]]) -> 3483.38 | R32: =AVERAGE(Table2[[#This Row],[Average Price(2022)]:[Average Price(2024)]]) -> 0.04143539
A33: LINDY VITAMIN E PH5.5 W 120 BAG | B33: Intelligent Initiative | C33: LINDY (Intelligent Initiative) | D33: BAGS | E33: PH BALANCED | F33: =IF('Working Sheet'!B43="ITEM",'Working Sheet'!E43,"") -> 120 | G33: =IF('Working Sheet'!B43="ITEM",'Working Sheet'!F43,"") -> 78.228 | H33: =IF('Working Sheet'!B43="ITEM",'Working Sheet'!G43,"") -> 99.0305 | I33: =IF('Working Sheet'!B43="ITEM",'Working Sheet'!H43,"") -> 56.6741 | J33: =IF('Working Sheet'!B43="ITEM",'Working Sheet'!I43,"") -> 4816.5708 | K33: =IF('Working Sheet'!B43="ITEM",'Working Sheet'!J43,"") -> 5822.6244 | L33: =IF('Working Sheet'!B43="ITEM",'Working Sheet'!K43,"") -> 2923.4183 | M33: =IFERROR(Table2[[#This Row],[Value(1000$) 2022]]/Table2[[#This Row],[Volume(1000) 2022]],0) -> 0.016241431 | N33: =IFERROR(Table2[[#This Row],[Value(1000$) 2023]]/Table2[[#This Row],[Volume(1000) 2023]],0) -> 0.017007881 | O33: =IFERROR(Table2[[#This Row],[Value(1000$) 2024]]/Table2[[#This Row],[Volume(1000) 2024]],0) -> 0.019386244 | P33: =SUM(Table2[[#This Row],[Value(1000$) 2022]:[Value(1000$) 2024]]) -> 233.9326 | Q33: =SUM(Table2[[#This Row],[Volume(1000) 2022]:[Volume(1000) 2024]]) -> 13562.613 | R33: =AVERAGE(Table2[[#This Row],[Average Price(2022)]:[Average Price(2024)]]) -> 0.017545185
